Workbook

Sheet Player Raw Data
A1: =IFERROR(__xludf.DUMMYFUNCTION("ARRAYFORMULA( IFERROR( SUBSTITUTE( IMPORTHTML(""https://www.basketball-reference.com/leagues/NBA_2027_totals.html"",""table"",1), ""*"",""""), IMPORTHTML(""https://www.basketball-reference.com/leagues/NBA_2027_totals.html"",""table"",1)))"),"Rk") -> Rk | B1: =IFERROR(__xludf.DUMMYFUNCTION("""COMPUTED_VALUE"""),"Player") -> Player | C1: =IFERROR(__xludf.DUMMYFUNCTION("""COMPUTED_VALUE"""),"Age") -> Age | D1: =IFERROR(__xludf.DUMMYFUNCTION("""COMPUTED_VALUE"""),"Team") -> Team | E1: =IFERROR(__xludf.DUMMYFUNCTION("""COMPUTED_VALUE"""),"Pos") -> Pos | F1: =IFERROR(__xludf.DUMMYFUNCTION("""COMPUTED_VALUE"""),"G") -> G | G1: =IFERROR(__xludf.DUMMYFUNCTION("""COMPUTED_VALUE"""),"GS") -> GS | H1: =IFERROR(__xludf.DUMMYFUNCTION("""COMPUTED_VALUE"""),"MP") -> MP | I1: =IFERROR(__xludf.DUMMYFUNCTION("""COMPUTED_VALUE"""),"FG") -> FG | J1: =IFERROR(__xludf.DUMMYFUNCTION("""COMPUTED_VALUE"""),"FGA") -> FGA | K1: =IFERROR(__xludf.DUMMYFUNCTION("""COMPUTED_VALUE"""),"FG%") -> FG% | L1: =IFERROR(__xludf.DUMMYFUNCTION("""COMPUTED_VALUE"""),"3P") -> 3P | M1: =IFERROR(__xludf.DUMMYFUNCTION("""COMPUTED_VALUE"""),"3PA") -> 3PA | N1: =IFERROR(__xludf.DUMMYFUNCTION("""COMPUTED_VALUE"""),"3P%") -> 3P% | O1: =IFERROR(__xludf.DUMMYFUNCTION("""COMPUTED_VALUE"""),"2P") -> 2P | P1: =IFERROR(__xludf.DUMMYFUNCTION("""COMPUTED_VALUE"""),"2PA") -> 2PA | Q1: =IFERROR(__xludf.DUMMYFUNCTION("""COMPUTED_VALUE"""),"2P%") -> 2P% | R1: =IFERROR(__xludf.DUMMYFUNCTION("""COMPUTED_VALUE"""),"eFG%") -> eFG% | S1: =IFERROR(__xludf.DUMMYFUNCTION("""COMPUTED_VALUE"""),"FT") -> FT | T1: =IFERROR(__xludf.DUMMYFUNCTION("""COMPUTED_VALUE"""),"FTA") -> FTA | U1: =IFERROR(__xludf.DUMMYFUNCTION("""COMPUTED_VALUE"""),"FT%") -> FT% | V1: =IFERROR(__xludf.DUMMYFUNCTION("""COMPUTED_VALUE"""),"ORB") -> ORB | W1: =IFERROR(__xludf.DUMMYFUNCTION("""COMPUTED_VALUE"""),"DRB") -> DRB | X1: =IFERROR(__xludf.DUMMYFUNCTION("""COMPUTED_VALUE"""),"TRB") -> TRB | Y1: =IFERROR(__xludf.DUMMYFUNCTION("""COMPUTED_VALUE"""),"AST") -> AST | Z1: =IFERROR(__xludf.DUMMYFUNCTION("""COMPUTED_VALUE"""),"STL") -> STL | AA1: =IFERROR(__xludf.DUMMYFUNCTION("""COMPUTED_VALUE"""),"BLK") -> BLK | AB1: =IFERROR(__xludf.DUMMYFUNCTION("""COMPUTED_VALUE"""),"TOV") -> TOV | AC1: =IFERROR(__xludf.DUMMYFUNCTION("""COMPUTED_VALUE"""),"PF") -> PF | AD1: =IFERROR(__xludf.DUMMYFUNCTION("""COMPUTED_VALUE"""),"PTS") -> PTS | AE1: =IFERROR(__xludf.DUMMYFUNCTION("""COMPUTED_VALUE"""),"Trp-Dbl") -> Trp-Dbl | AF1: =IFERROR(__xludf.DUMMYFUNCTION("""COMPUTED_VALUE"""),"Awards") -> Awards
A2: =IFERROR(__xludf.DUMMYFUNCTION("""COMPUTED_VALUE"""),"1") -> 1 | B2: =IFERROR(__xludf.DUMMYFUNCTION("""COMPUTED_VALUE"""),"Paul George") -> Paul George | C2: =IFERROR(__xludf.DUMMYFUNCTION("""COMPUTED_VALUE"""),"36") -> 36 | D2: =IFERROR(__xludf.DUMMYFUNCTION("""COMPUTED_VALUE"""),"BOS") -> BOS | E2: =IFERROR(__xludf.DUMMYFUNCTION("""COMPUTED_VALUE"""),"PF") -> PF | F2: =IFERROR(__xludf.DUMMYFUNCTION("""COMPUTED_VALUE"""),"1") -> 1 | G2: =IFERROR(__xludf.DUMMYFUNCTION("""COMPUTED_VALUE"""),"1") -> 1 | H2: =IFERROR(__xludf.DUMMYFUNCTION("""COMPUTED_VALUE"""),"31") -> 31 | I2: =IFERROR(__xludf.DUMMYFUNCTION("""COMPUTED_VALUE"""),"12") -> 12 | J2: =IFERROR(__xludf.DUMMYFUNCTION("""COMPUTED_VALUE"""),"21") -> 21 | K2: =IFERROR(__xludf.DUMMYFUNCTION("""COMPUTED_VALUE"""),"0.571") -> 0.571 | L2: =IFERROR(__xludf.DUMMYFUNCTION("""COMPUTED_VALUE"""),"7") -> 7 | M2: =IFERROR(__xludf.DUMMYFUNCTION("""COMPUTED_VALUE"""),"12") -> 12 | N2: =IFERROR(__xludf.DUMMYFUNCTION("""COMPUTED_VALUE"""),"0.583") -> 0.583 | O2: =IFERROR(__xludf.DUMMYFUNCTION("""COMPUTED_VALUE"""),"5") -> 5 | P2: =IFERROR(__xludf.DUMMYFUNCTION("""COMPUTED_VALUE"""),"9") -> 9 | Q2: =IFERROR(__xludf.DUMMYFUNCTION("""COMPUTED_VALUE"""),"0.556") -> 0.556 | R2: =IFERROR(__xludf.DUMMYFUNCTION("""COMPUTED_VALUE"""),"0.738") -> 0.738 | S2: =IFERROR(__xludf.DUMMYFUNCTION("""COMPUTED_VALUE"""),"7") -> 7 | T2: =IFERROR(__xludf.DUMMYFUNCTION("""COMPUTED_VALUE"""),"8") -> 8 | U2: =IFERROR(__xludf.DUMMYFUNCTION("""COMPUTED_VALUE"""),"0.875") -> 0.875 | V2: =IFERROR(__xludf.DUMMYFUNCTION("""COMPUTED_VALUE"""),"0") -> 0 | W2: =IFERROR(__xludf.DUMMYFUNCTION("""COMPUTED_VALUE"""),"5") -> 5 | X2: =IFERROR(__xludf.DUMMYFUNCTION("""COMPUTED_VALUE"""),"5") -> 5 | Y2: =IFERROR(__xludf.DUMMYFUNCTION("""COMPUTED_VALUE"""),"3") -> 3 | Z2: =IFERROR(__xludf.DUMMYFUNCTION("""COMPUTED_VALUE"""),"5") -> 5 | AA2: =IFERROR(__xludf.DUMMYFUNCTION("""COMPUTED_VALUE"""),"0") -> 0 | AB2: =IFERROR(__xludf.DUMMYFUNCTION("""COMPUTED_VALUE"""),"3") -> 3 | AC2: =IFERROR(__xludf.DUMMYFUNCTION("""COMPUTED_VALUE"""),"5") -> 5 | AD2: =IFERROR(__xludf.DUMMYFUNCTION("""COMPUTED_VALUE"""),"38") -> 38 | AE2: =IFERROR(__xludf.DUMMYFUNCTION("""COMPUTED_VALUE"""),"0") -> 0 | AF2: =IFERROR(__xludf.DUMMYFUNCTION("""COMPUTED_VALUE"""),"")
A3: =IFERROR(__xludf.DUMMYFUNCTION("""COMPUTED_VALUE"""),"2") -> 2 | B3: =IFERROR(__xludf.DUMMYFUNCTION("""COMPUTED_VALUE"""),"Shai Gilgeous-Alexander") -> Shai Gilgeous-Alexander | C3: =IFERROR(__xludf.DUMMYFUNCTION("""COMPUTED_VALUE"""),"28") -> 28 | D3: =IFERROR(__xludf.DUMMYFUNCTION("""COMPUTED_VALUE"""),"OKC") -> OKC | E3: =IFERROR(__xludf.DUMMYFUNCTION("""COMPUTED_VALUE"""),"PG") -> PG | F3: =IFERROR(__xludf.DUMMYFUNCTION("""COMPUTED_VALUE"""),"1") -> 1 | G3: =IFERROR(__xludf.DUMMYFUNCTION("""COMPUTED_VALUE"""),"1") -> 1 | H3: =IFERROR(__xludf.DUMMYFUNCTION("""COMPUTED_VALUE"""),"36") -> 36 | I3: =IFERROR(__xludf.DUMMYFUNCTION("""COMPUTED_VALUE"""),"13") -> 13 | J3: =IFERROR(__xludf.DUMMYFUNCTION("""COMPUTED_VALUE"""),"27") -> 27 | K3: =IFERROR(__xludf.DUMMYFUNCTION("""COMPUTED_VALUE"""),"0.481") -> 0.481 | L3: =IFERROR(__xludf.DUMMYFUNCTION("""COMPUTED_VALUE"""),"3") -> 3 | M3: =IFERROR(__xludf.DUMMYFUNCTION("""COMPUTED_VALUE"""),"7") -> 7 | N3: =IFERROR(__xludf.DUMMYFUNCTION("""COMPUTED_VALUE"""),"0.429") -> 0.429 | O3: =IFERROR(__xludf.DUMMYFUNCTION("""COMPUTED_VALUE"""),"10") -> 10 | P3: =IFERROR(__xludf.DUMMYFUNCTION("""COMPUTED_VALUE"""),"20") -> 20 | Q3: =IFERROR(__xludf.DUMMYFUNCTION("""COMPUTED_VALUE"""),"0.5") -> 0.5 | R3: =IFERROR(__xludf.DUMMYFUNCTION("""COMPUTED_VALUE"""),"0.537") -> 0.537 | S3: =IFERROR(__xludf.DUMMYFUNCTION("""COMPUTED_VALUE"""),"3") -> 3 | T3: =IFERROR(__xludf.DUMMYFUNCTION("""COMPUTED_VALUE"""),"4") -> 4 | U3: =IFERROR(__xludf.DUMMYFUNCTION("""COMPUTED_VALUE"""),"0.75") -> 0.75 | V3: =IFERROR(__xludf.DUMMYFUNCTION("""COMPUTED_VALUE"""),"2") -> 2 | W3: =IFERROR(__xludf.DUMMYFUNCTION("""COMPUTED_VALUE"""),"4") -> 4 | X3: =IFERROR(__xludf.DUMMYFUNCTION("""COMPUTED_VALUE"""),"6") -> 6 | Y3: =IFERROR(__xludf.DUMMYFUNCTION("""COMPUTED_VALUE"""),"4") -> 4 | Z3: =IFERROR(__xludf.DUMMYFUNCTION("""COMPUTED_VALUE"""),"3") -> 3 | AA3: =IFERROR(__xludf.DUMMYFUNCTION("""COMPUTED_VALUE"""),"3") -> 3 | AB3: =IFERROR(__xludf.DUMMYFUNCTION("""COMPUTED_VALUE"""),"2") -> 2 | AC3: =IFERROR(__xludf.DUMMYFUNCTION("""COMPUTED_VALUE"""),"2") -> 2 | AD3: =IFERROR(__xludf.DUMMYFUNCTION("""COMPUTED_VALUE"""),"32") -> 32 | AE3: =IFERROR(__xludf.DUMMYFUNCTION("""COMPUTED_VALUE"""),"0") -> 0 | AF3: =IFERROR(__xludf.DUMMYFUNCTION("""COMPUTED_VALUE"""),"")
A4: =IFERROR(__xludf.DUMMYFUNCTION("""COMPUTED_VALUE"""),"3") -> 3 | B4: =IFERROR(__xludf.DUMMYFUNCTION("""COMPUTED_VALUE"""),"Tyrese Maxey") -> Tyrese Maxey | C4: =IFERROR(__xludf.DUMMYFUNCTION("""COMPUTED_VALUE"""),"26") -> 26 | D4: =IFERROR(__xludf.DUMMYFUNCTION("""COMPUTED_VALUE"""),"PHI") -> PHI | E4: =IFERROR(__xludf.DUMMYFUNCTION("""COMPUTED_VALUE"""),"PG") -> PG | F4: =IFERROR(__xludf.DUMMYFUNCTION("""COMPUTED_VALUE"""),"1") -> 1 | G4: =IFERROR(__xludf.DUMMYFUNCTION("""COMPUTED_VALUE"""),"1") -> 1 | H4: =IFERROR(__xludf.DUMMYFUNCTION("""COMPUTED_VALUE"""),"40") -> 40 | I4: =IFERROR(__xludf.DUMMYFUNCTION("""COMPUTED_VALUE"""),"9") -> 9 | J4: =IFERROR(__xludf.DUMMYFUNCTION("""COMPUTED_VALUE"""),"19") -> 19 | K4: =IFERROR(__xludf.DUMMYFUNCTION("""COMPUTED_VALUE"""),"0.474") -> 0.474 | L4: =IFERROR(__xludf.DUMMYFUNCTION("""COMPUTED_VALUE"""),"2") -> 2 | M4: =IFERROR(__xludf.DUMMYFUNCTION("""COMPUTED_VALUE"""),"9") -> 9 | N4: =IFERROR(__xludf.DUMMYFUNCTION("""COMPUTED_VALUE"""),"0.222") -> 0.222 | O4: =IFERROR(__xludf.DUMMYFUNCTION("""COMPUTED_VALUE"""),"7") -> 7 | P4: =IFERROR(__xludf.DUMMYFUNCTION("""COMPUTED_VALUE"""),"10") -> 10 | Q4: =IFERROR(__xludf.DUMMYFUNCTION("""COMPUTED_VALUE"""),"0.7") -> 0.7 | R4: =IFERROR(__xludf.DUMMYFUNCTION("""COMPUTED_VALUE"""),"0.526") -> 0.526 | S4: =IFERROR(__xludf.DUMMYFUNCTION("""COMPUTED_VALUE"""),"8") -> 8 | T4: =IFERROR(__xludf.DUMMYFUNCTION("""COMPUTED_VALUE"""),"9") -> 9 | U4: =IFERROR(__xludf.DUMMYFUNCTION("""COMPUTED_VALUE"""),"0.889") -> 0.889 | V4: =IFERROR(__xludf.DUMMYFUNCTION("""COMPUTED_VALUE"""),"1") -> 1 | W4: =IFERROR(__xludf.DUMMYFUNCTION("""COMPUTED_VALUE"""),"3") -> 3 | X4: =IFERROR(__xludf.DUMMYFUNCTION("""COMPUTED_VALUE"""),"4") -> 4 | Y4: =IFERROR(__xludf.DUMMYFUNCTION("""COMPUTED_VALUE"""),"5") -> 5 | Z4: =IFERROR(__xludf.DUMMYFUNCTION("""COMPUTED_VALUE"""),"3") -> 3 | AA4: =IFERROR(__xludf.DUMMYFUNCTION("""COMPUTED_VALUE"""),"3") -> 3 | AB4: =IFERROR(__xludf.DUMMYFUNCTION("""COMPUTED_VALUE"""),"2") -> 2 | AC4: =IFERROR(__xludf.DUMMYFUNCTION("""COMPUTED_VALUE"""),"3") -> 3 | AD4: =IFERROR(__xludf.DUMMYFUNCTION("""COMPUTED_VALUE"""),"28") -> 28 | AE4: =IFERROR(__xludf.DUMMYFUNCTION("""COMPUTED_VALUE"""),"0") -> 0 | AF4: =IFERROR(__xludf.DUMMYFUNCTION("""COMPUTED_VALUE"""),"")
A5: =IFERROR(__xludf.DUMMYFUNCTION("""COMPUTED_VALUE"""),"4") -> 4 | B5: =IFERROR(__xludf.DUMMYFUNCTION("""COMPUTED_VALUE"""),"Stephon Castle") -> Stephon Castle | C5: =IFERROR(__xludf.DUMMYFUNCTION("""COMPUTED_VALUE"""),"22") -> 22 | D5: =IFERROR(__xludf.DUMMYFUNCTION("""COMPUTED_VALUE"""),"SAS") -> SAS | E5: =IFERROR(__xludf.DUMMYFUNCTION("""COMPUTED_VALUE"""),"PG") -> PG | F5: =IFERROR(__xludf.DUMMYFUNCTION("""COMPUTED_VALUE"""),"1") -> 1 | G5: =IFERROR(__xludf.DUMMYFUNCTION("""COMPUTED_VALUE"""),"1") -> 1 | H5: =IFERROR(__xludf.DUMMYFUNCTION("""COMPUTED_VALUE"""),"28") -> 28 | I5: =IFERROR(__xludf.DUMMYFUNCTION("""COMPUTED_VALUE"""),"9") -> 9 | J5: =IFERROR(__xludf.DUMMYFUNCTION("""COMPUTED_VALUE"""),"21") -> 21 | K5: =IFERROR(__xludf.DUMMYFUNCTION("""COMPUTED_VALUE"""),"0.429") -> 0.429 | L5: =IFERROR(__xludf.DUMMYFUNCTION("""COMPUTED_VALUE"""),"5") -> 5 | M5: =IFERROR(__xludf.DUMMYFUNCTION("""COMPUTED_VALUE"""),"12") -> 12 | N5: =IFERROR(__xludf.DUMMYFUNCTION("""COMPUTED_VALUE"""),"0.417") -> 0.417 | O5: =IFERROR(__xludf.DUMMYFUNCTION("""COMPUTED_VALUE"""),"4") -> 4 | P5: =IFERROR(__xludf.DUMMYFUNCTION("""COMPUTED_VALUE"""),"9") -> 9 | Q5: =IFERROR(__xludf.DUMMYFUNCTION("""COMPUTED_VALUE"""),"0.444") -> 0.444 | R5: =IFERROR(__xludf.DUMMYFUNCTION("""COMPUTED_VALUE"""),"0.548") -> 0.548 | S5: =IFERROR(__xludf.DUMMYFUNCTION("""COMPUTED_VALUE"""),"1") -> 1 | T5: =IFERROR(__xludf.DUMMYFUNCTION("""COMPUTED_VALUE"""),"1") -> 1 | U5: =IFERROR(__xludf.DUMMYFUNCTION("""COMPUTED_VALUE"""),"1") -> 1 | V5: =IFERROR(__xludf.DUMMYFUNCTION("""COMPUTED_VALUE"""),"2") -> 2 | W5: =IFERROR(__xludf.DUMMYFUNCTION("""COMPUTED_VALUE"""),"5") -> 5 | X5: =IFERROR(__xludf.DUMMYFUNCTION("""COMPUTED_VALUE"""),"7") -> 7 | Y5: =IFERROR(__xludf.DUMMYFUNCTION("""COMPUTED_VALUE"""),"1") -> 1 | Z5: =IFERROR(__xludf.DUMMYFUNCTION("""COMPUTED_VALUE"""),"0") -> 0 | AA5: =IFERROR(__xludf.DUMMYFUNCTION("""COMPUTED_VALUE"""),"0") -> 0 | AB5: =IFERROR(__xludf.DUMMYFUNCTION("""COMPUTED_VALUE"""),"3") -> 3 | AC5: =IFERROR(__xludf.DUMMYFUNCTION("""COMPUTED_VALUE"""),"4") -> 4 | AD5: =IFERROR(__xludf.DUMMYFUNCTION("""COMPUTED_VALUE"""),"24") -> 24 | AE5: =IFERROR(__xludf.DUMMYFUNCTION("""COMPUTED_VALUE"""),"0") -> 0 | AF5: =IFERROR(__xludf.DUMMYFUNCTION("""COMPUTED_VALUE"""),"")
A6: =IFERROR(__xludf.DUMMYFUNCTION("""COMPUTED_VALUE"""),"5") -> 5 | B6: =IFERROR(__xludf.DUMMYFUNCTION("""COMPUTED_VALUE"""),"Cade Cunningham") -> Cade Cunningham | C6: =IFERROR(__xludf.DUMMYFUNCTION("""COMPUTED_VALUE"""),"25") -> 25 | D6: =IFERROR(__xludf.DUMMYFUNCTION("""COMPUTED_VALUE"""),"DET") -> DET | E6: =IFERROR(__xludf.DUMMYFUNCTION("""COMPUTED_VALUE"""),"PG") -> PG | F6: =IFERROR(__xludf.DUMMYFUNCTION("""COMPUTED_VALUE"""),"1") -> 1 | G6: =IFERROR(__xludf.DUMMYFUNCTION("""COMPUTED_VALUE"""),"1") -> 1 | H6: =IFERROR(__xludf.DUMMYFUNCTION("""COMPUTED_VALUE"""),"35") -> 35 | I6: =IFERROR(__xludf.DUMMYFUNCTION("""COMPUTED_VALUE"""),"8") -> 8 | J6: =IFERROR(__xludf.DUMMYFUNCTION("""COMPUTED_VALUE"""),"18") -> 18 | K6: =IFERROR(__xludf.DUMMYFUNCTION("""COMPUTED_VALUE"""),"0.444") -> 0.444 | L6: =IFERROR(__xludf.DUMMYFUNCTION("""COMPUTED_VALUE"""),"1") -> 1 | M6: =IFERROR(__xludf.DUMMYFUNCTION("""COMPUTED_VALUE"""),"6") -> 6 | N6: =IFERROR(__xludf.DUMMYFUNCTION("""COMPUTED_VALUE"""),"0.167") -> 0.167 | O6: =IFERROR(__xludf.DUMMYFUNCTION("""COMPUTED_VALUE"""),"7") -> 7 | P6: =IFERROR(__xludf.DUMMYFUNCTION("""COMPUTED_VALUE"""),"12") -> 12 | Q6: =IFERROR(__xludf.DUMMYFUNCTION("""COMPUTED_VALUE"""),"0.583") -> 0.583 | R6: =IFERROR(__xludf.DUMMYFUNCTION("""COMPUTED_VALUE"""),"0.472") -> 0.472 | S6: =IFERROR(__xludf.DUMMYFUNCTION("""COMPUTED_VALUE"""),"5") -> 5 | T6: =IFERROR(__xludf.DUMMYFUNCTION("""COMPUTED_VALUE"""),"5") -> 5 | U6: =IFERROR(__xludf.DUMMYFUNCTION("""COMPUTED_VALUE"""),"1.000") -> 1.000 | V6: =IFERROR(__xludf.DUMMYFUNCTION("""COMPUTED_VALUE"""),"0") -> 0 | W6: =IFERROR(__xludf.DUMMYFUNCTION("""COMPUTED_VALUE"""),"4") -> 4 | X6: =IFERROR(__xludf.DUMMYFUNCTION("""COMPUTED_VALUE"""),"4") -> 4 | Y6: =IFERROR(__xludf.DUMMYFUNCTION("""COMPUTED_VALUE"""),"8") -> 8 | Z6: =IFERROR(__xludf.DUMMYFUNCTION("""COMPUTED_VALUE"""),"1") -> 1 | AA6: =IFERROR(__xludf.DUMMYFUNCTION("""COMPUTED_VALUE"""),"1") -> 1 | AB6: =IFERROR(__xludf.DUMMYFUNCTION("""COMPUTED_VALUE"""),"5") -> 5 | AC6: =IFERROR(__xludf.DUMMYFUNCTION("""COMPUTED_VALUE"""),"0") -> 0 | AD6: =IFERROR(__xludf.DUMMYFUNCTION("""COMPUTED_VALUE"""),"22") -> 22 | AE6: =IFERROR(__xludf.DUMMYFUNCTION("""COMPUTED_VALUE"""),"0") -> 0 | AF6: =IFERROR(__xludf.DUMMYFUNCTION("""COMPUTED_VALUE"""),"")
A7: =IFERROR(__xludf.DUMMYFUNCTION("""COMPUTED_VALUE"""),"6") -> 6 | B7: =IFERROR(__xludf.DUMMYFUNCTION("""COMPUTED_VALUE"""),"Jalen Duren") -> Jalen Duren | C7: =IFERROR(__xludf.DUMMYFUNCTION("""COMPUTED_VALUE"""),"23") -> 23 | D7: =IFERROR(__xludf.DUMMYFUNCTION("""COMPUTED_VALUE"""),"DET") -> DET | E7: =IFERROR(__xludf.DUMMYFUNCTION("""COMPUTED_VALUE"""),"C") -> C | F7: =IFERROR(__xludf.DUMMYFUNCTION("""COMPUTED_VALUE"""),"1") -> 1 | G7: =IFERROR(__xludf.DUMMYFUNCTION("""COMPUTED_VALUE"""),"1") -> 1 | H7: =IFERROR(__xludf.DUMMYFUNCTION("""COMPUTED_VALUE"""),"28") -> 28 | I7: =IFERROR(__xludf.DUMMYFUNCTION("""COMPUTED_VALUE"""),"8") -> 8 | J7: =IFERROR(__xludf.DUMMYFUNCTION("""COMPUTED_VALUE"""),"13") -> 13 | K7: =IFERROR(__xludf.DUMMYFUNCTION("""COMPUTED_VALUE"""),"0.615") -> 0.615 | L7: =IFERROR(__xludf.DUMMYFUNCTION("""COMPUTED_VALUE"""),"0") -> 0 | M7: =IFERROR(__xludf.DUMMYFUNCTION("""COMPUTED_VALUE"""),"0") -> 0 | N7: =IFERROR(__xludf.DUMMYFUNCTION("""COMPUTED_VALUE"""),"") | O7: =IFERROR(__xludf.DUMMYFUNCTION("""COMPUTED_VALUE"""),"8") -> 8 | P7: =IFERROR(__xludf.DUMMYFUNCTION("""COMPUTED_VALUE"""),"13") -> 13 | Q7: =IFERROR(__xludf.DUMMYFUNCTION("""COMPUTED_VALUE"""),"0.615") -> 0.615 | R7: =IFERROR(__xludf.DUMMYFUNCTION("""COMPUTED_VALUE"""),"0.615") -> 0.615 | S7: =IFERROR(__xludf.DUMMYFUNCTION("""COMPUTED_VALUE"""),"6") -> 6 | T7: =IFERROR(__xludf.DUMMYFUNCTION("""COMPUTED_VALUE"""),"7") -> 7 | U7: =IFERROR(__xludf.DUMMYFUNCTION("""COMPUTED_VALUE"""),"0.857") -> 0.857 | V7: =IFERROR(__xludf.DUMMYFUNCTION("""COMPUTED_VALUE"""),"3") -> 3 | W7: =IFERROR(__xludf.DUMMYFUNCTION("""COMPUTED_VALUE"""),"6") -> 6 | X7: =IFERROR(__xludf.DUMMYFUNCTION("""COMPUTED_VALUE"""),"9") -> 9 | Y7: =IFERROR(__xludf.DUMMYFUNCTION("""COMPUTED_VALUE"""),"1") -> 1 | Z7: =IFERROR(__xludf.DUMMYFUNCTION("""COMPUTED_VALUE"""),"1") -> 1 | AA7: =IFERROR(__xludf.DUMMYFUNCTION("""COMPUTED_VALUE"""),"1") -> 1 | AB7: =IFERROR(__xludf.DUMMYFUNCTION("""COMPUTED_VALUE"""),"1") -> 1 | AC7: =IFERROR(__xludf.DUMMYFUNCTION("""COMPUTED_VALUE"""),"2") -> 2 | AD7: =IFERROR(__xludf.DUMMYFUNCTION("""COMPUTED_VALUE"""),"22") -> 22 | AE7: =IFERROR(__xludf.DUMMYFUNCTION("""COMPUTED_VALUE"""),"0") -> 0 | AF7: =IFERROR(__xludf.DUMMYFUNCTION("""COMPUTED_VALUE"""),"")
A8: =IFERROR(__xludf.DUMMYFUNCTION("""COMPUTED_VALUE"""),"7") -> 7 | B8: =IFERROR(__xludf.DUMMYFUNCTION("""COMPUTED_VALUE"""),"Jalen Brunson") -> Jalen Brunson | C8: =IFERROR(__xludf.DUMMYFUNCTION("""COMPUTED_VALUE"""),"30") -> 30 | D8: =IFERROR(__xludf.DUMMYFUNCTION("""COMPUTED_VALUE"""),"NYK") -> NYK | E8: =IFERROR(__xludf.DUMMYFUNCTION("""COMPUTED_VALUE"""),"PG") -> PG | F8: =IFERROR(__xludf.DUMMYFUNCTION("""COMPUTED_VALUE"""),"1") -> 1 | G8: =IFERROR(__xludf.DUMMYFUNCTION("""COMPUTED_VALUE"""),"1") -> 1 | H8: =IFERROR(__xludf.DUMMYFUNCTION("""COMPUTED_VALUE"""),"34") -> 34 | I8: =IFERROR(__xludf.DUMMYFUNCTION("""COMPUTED_VALUE"""),"6") -> 6 | J8: =IFERROR(__xludf.DUMMYFUNCTION("""COMPUTED_VALUE"""),"19") -> 19 | K8: =IFERROR(__xludf.DUMMYFUNCTION("""COMPUTED_VALUE"""),"0.316") -> 0.316 | L8: =IFERROR(__xludf.DUMMYFUNCTION("""COMPUTED_VALUE"""),"1") -> 1 | M8: =IFERROR(__xludf.DUMMYFUNCTION("""COMPUTED_VALUE"""),"3") -> 3 | N8: =IFERROR(__xludf.DUMMYFUNCTION("""COMPUTED_VALUE"""),"0.333") -> 0.333 | O8: =IFERROR(__xludf.DUMMYFUNCTION("""COMPUTED_VALUE"""),"5") -> 5 | P8: =IFERROR(__xludf.DUMMYFUNCTION("""COMPUTED_VALUE"""),"16") -> 16 | Q8: =IFERROR(__xludf.DUMMYFUNCTION("""COMPUTED_VALUE"""),"0.313") -> 0.313 | R8: =IFERROR(__xludf.DUMMYFUNCTION("""COMPUTED_VALUE"""),"0.342") -> 0.342 | S8: =IFERROR(__xludf.DUMMYFUNCTION("""COMPUTED_VALUE"""),"8") -> 8 | T8: =IFERROR(__xludf.DUMMYFUNCTION("""COMPUTED_VALUE"""),"8") -> 8 | U8: =IFERROR(__xludf.DUMMYFUNCTION("""COMPUTED_VALUE"""),"1.000") -> 1.000 | V8: =IFERROR(__xludf.DUMMYFUNCTION("""COMPUTED_VALUE"""),"0") -> 0 | W8: =IFERROR(__xludf.DUMMYFUNCTION("""COMPUTED_VALUE"""),"5") -> 5 | X8: =IFERROR(__xludf.DUMMYFUNCTION("""COMPUTED_VALUE"""),"5") -> 5 | Y8: =IFERROR(__xludf.DUMMYFUNCTION("""COMPUTED_VALUE"""),"3") -> 3 | Z8: =IFERROR(__xludf.DUMMYFUNCTION("""COMPUTED_VALUE"""),"0") -> 0 | AA8: =IFERROR(__xludf.DUMMYFUNCTION("""COMPUTED_VALUE"""),"0") -> 0 | AB8: =IFERROR(__xludf.DUMMYFUNCTION("""COMPUTED_VALUE"""),"2") -> 2 | AC8: =IFERROR(__xludf.DUMMYFUNCTION("""COMPUTED_VALUE"""),"1") -> 1 | AD8: =IFERROR(__xludf.DUMMYFUNCTION("""COMPUTED_VALUE"""),"21") -> 21 | AE8: =IFERROR(__xludf.DUMMYFUNCTION("""COMPUTED_VALUE"""),"0") -> 0 | AF8: =IFERROR(__xludf.DUMMYFUNCTION("""COMPUTED_VALUE"""),"")
A9: =IFERROR(__xludf.DUMMYFUNCTION("""COMPUTED_VALUE"""),"8") -> 8 | B9: =IFERROR(__xludf.DUMMYFUNCTION("""COMPUTED_VALUE"""),"Duncan Robinson") -> Duncan Robinson | C9: =IFERROR(__xludf.DUMMYFUNCTION("""COMPUTED_VALUE"""),"32") -> 32 | D9: =IFERROR(__xludf.DUMMYFUNCTION("""COMPUTED_VALUE"""),"DET") -> DET | E9: =IFERROR(__xludf.DUMMYFUNCTION("""COMPUTED_VALUE"""),"SF") -> SF | F9: =IFERROR(__xludf.DUMMYFUNCTION("""COMPUTED_VALUE"""),"1") -> 1 | G9: =IFERROR(__xludf.DUMMYFUNCTION("""COMPUTED_VALUE"""),"1") -> 1 | H9: =IFERROR(__xludf.DUMMYFUNCTION("""COMPUTED_VALUE"""),"28") -> 28 | I9: =IFERROR(__xludf.DUMMYFUNCTION("""COMPUTED_VALUE"""),"5") -> 5 | J9: =IFERROR(__xludf.DUMMYFUNCTION("""COMPUTED_VALUE"""),"10") -> 10 | K9: =IFERROR(__xludf.DUMMYFUNCTION("""COMPUTED_VALUE"""),"0.5") -> 0.5 | L9: =IFERROR(__xludf.DUMMYFUNCTION("""COMPUTED_VALUE"""),"5") -> 5 | M9: =IFERROR(__xludf.DUMMYFUNCTION("""COMPUTED_VALUE"""),"9") -> 9 | N9: =IFERROR(__xludf.DUMMYFUNCTION("""COMPUTED_VALUE"""),"0.556") -> 0.556 | O9: =IFERROR(__xludf.DUMMYFUNCTION("""COMPUTED_VALUE"""),"0") -> 0 | P9: =IFERROR(__xludf.DUMMYFUNCTION("""COMPUTED_VALUE"""),"1") -> 1 | Q9: =IFERROR(__xludf.DUMMYFUNCTION("""COMPUTED_VALUE"""),"0") -> 0 | R9: =IFERROR(__xludf.DUMMYFUNCTION("""COMPUTED_VALUE"""),"0.75") -> 0.75 | S9: =IFERROR(__xludf.DUMMYFUNCTION("""COMPUTED_VALUE"""),"6") -> 6 | T9: =IFERROR(__xludf.DUMMYFUNCTION("""COMPUTED_VALUE"""),"8") -> 8 | U9: =IFERROR(__xludf.DUMMYFUNCTION("""COMPUTED_VALUE"""),"0.75") -> 0.75 | V9: =IFERROR(__xludf.DUMMYFUNCTION("""COMPUTED_VALUE"""),"0") -> 0 | W9: =IFERROR(__xludf.DUMMYFUNCTION("""COMPUTED_VALUE"""),"2") -> 2 | X9: =IFERROR(__xludf.DUMMYFUNCTION("""COMPUTED_VALUE"""),"2") -> 2 | Y9: =IFERROR(__xludf.DUMMYFUNCTION("""COMPUTED_VALUE"""),"2") -> 2 | Z9: =IFERROR(__xludf.DUMMYFUNCTION("""COMPUTED_VALUE"""),"1") -> 1 | AA9: =IFERROR(__xludf.DUMMYFUNCTION("""COMPUTED_VALUE"""),"0") -> 0 | AB9: =IFERROR(__xludf.DUMMYFUNCTION("""COMPUTED_VALUE"""),"3") -> 3 | AC9: =IFERROR(__xludf.DUMMYFUNCTION("""COMPUTED_VALUE"""),"4") -> 4 | AD9: =IFERROR(__xludf.DUMMYFUNCTION("""COMPUTED_VALUE"""),"21") -> 21 | AE9: =IFERROR(__xludf.DUMMYFUNCTION("""COMPUTED_VALUE"""),"0") -> 0 | AF9: =IFERROR(__xludf.DUMMYFUNCTION("""COMPUTED_VALUE"""),"")
A10: =IFERROR(__xludf.DUMMYFUNCTION("""COMPUTED_VALUE"""),"9") -> 9 | B10: =IFERROR(__xludf.DUMMYFUNCTION("""COMPUTED_VALUE"""),"Jared McCain") -> Jared McCain | C10: =IFERROR(__xludf.DUMMYFUNCTION("""COMPUTED_VALUE"""),"22") -> 22 | D10: =IFERROR(__xludf.DUMMYFUNCTION("""COMPUTED_VALUE"""),"OKC") -> OKC | E10: =IFERROR(__xludf.DUMMYFUNCTION("""COMPUTED_VALUE"""),"SG") -> SG | F10: =IFERROR(__xludf.DUMMYFUNCTION("""COMPUTED_VALUE"""),"1") -> 1 | G10: =IFERROR(__xludf.DUMMYFUNCTION("""COMPUTED_VALUE"""),"0") -> 0 | H10: =IFERROR(__xludf.DUMMYFUNCTION("""COMPUTED_VALUE"""),"22") -> 22 | I10: =IFERROR(__xludf.DUMMYFUNCTION("""COMPUTED_VALUE"""),"7") -> 7 | J10: =IFERROR(__xludf.DUMMYFUNCTION("""COMPUTED_VALUE"""),"9") -> 9 | K10: =IFERROR(__xludf.DUMMYFUNCTION("""COMPUTED_VALUE"""),".778") -> .778 | L10: =IFERROR(__xludf.DUMMYFUNCTION("""COMPUTED_VALUE"""),"6") -> 6 | M10: =IFERROR(__xludf.DUMMYFUNCTION("""COMPUTED_VALUE"""),"8") -> 8 | N10: =IFERROR(__xludf.DUMMYFUNCTION("""COMPUTED_VALUE"""),"0.75") -> 0.75 | O10: =IFERROR(__xludf.DUMMYFUNCTION("""COMPUTED_VALUE"""),"1") -> 1 | P10: =IFERROR(__xludf.DUMMYFUNCTION("""COMPUTED_VALUE"""),"1") -> 1 | Q10: =IFERROR(__xludf.DUMMYFUNCTION("""COMPUTED_VALUE"""),"1.000") -> 1.000 | R10: =IFERROR(__xludf.DUMMYFUNCTION("""COMPUTED_VALUE"""),"1.111") -> 1.111 | S10: =IFERROR(__xludf.DUMMYFUNCTION("""COMPUTED_VALUE"""),"0") -> 0 | T10: =IFERROR(__xludf.DUMMYFUNCTION("""COMPUTED_VALUE"""),"0") -> 0 | U10: =IFERROR(__xludf.DUMMYFUNCTION("""COMPUTED_VALUE"""),"") | V10: =IFERROR(__xludf.DUMMYFUNCTION("""COMPUTED_VALUE"""),"0") -> 0 | W10: =IFERROR(__xludf.DUMMYFUNCTION("""COMPUTED_VALUE"""),"2") -> 2 | X10: =IFERROR(__xludf.DUMMYFUNCTION("""COMPUTED_VALUE"""),"2") -> 2 | Y10: =IFERROR(__xludf.DUMMYFUNCTION("""COMPUTED_VALUE"""),"2") -> 2 | Z10: =IFERROR(__xludf.DUMMYFUNCTION("""COMPUTED_VALUE"""),"1") -> 1 | AA10: =IFERROR(__xludf.DUMMYFUNCTION("""COMPUTED_VALUE"""),"0") -> 0 | AB10: =IFERROR(__xludf.DUMMYFUNCTION("""COMPUTED_VALUE"""),"2") -> 2 | AC10: =IFERROR(__xludf.DUMMYFUNCTION("""COMPUTED_VALUE"""),"1") -> 1 | AD10: =IFERROR(__xludf.DUMMYFUNCTION("""COMPUTED_VALUE"""),"20") -> 20 | AE10: =IFERROR(__xludf.DUMMYFUNCTION("""COMPUTED_VALUE"""),"0") -> 0 | AF10: =IFERROR(__xludf.DUMMYFUNCTION("""COMPUTED_VALUE"""),"")
A11: =IFERROR(__xludf.DUMMYFUNCTION("""COMPUTED_VALUE"""),"10") -> 10 | B11: =IFERROR(__xludf.DUMMYFUNCTION("""COMPUTED_VALUE"""),"Jaylen Brown") -> Jaylen Brown | C11: =IFERROR(__xludf.DUMMYFUNCTION("""COMPUTED_VALUE"""),"30") -> 30 | D11: =IFERROR(__xludf.DUMMYFUNCTION("""COMPUTED_VALUE"""),"PHI") -> PHI | E11: =IFERROR(__xludf.DUMMYFUNCTION("""COMPUTED_VALUE"""),"SF") -> SF | F11: =IFERROR(__xludf.DUMMYFUNCTION("""COMPUTED_VALUE"""),"1") -> 1 | G11: =IFERROR(__xludf.DUMMYFUNCTION("""COMPUTED_VALUE"""),"1") -> 1 | H11: =IFERROR(__xludf.DUMMYFUNCTION("""COMPUTED_VALUE"""),"35") -> 35 | I11: =IFERROR(__xludf.DUMMYFUNCTION("""COMPUTED_VALUE"""),"7") -> 7 | J11: =IFERROR(__xludf.DUMMYFUNCTION("""COMPUTED_VALUE"""),"14") -> 14 | K11: =IFERROR(__xludf.DUMMYFUNCTION("""COMPUTED_VALUE"""),"0.5") -> 0.5 | L11: =IFERROR(__xludf.DUMMYFUNCTION("""COMPUTED_VALUE"""),"2") -> 2 | M11: =IFERROR(__xludf.DUMMYFUNCTION("""COMPUTED_VALUE"""),"4") -> 4 | N11: =IFERROR(__xludf.DUMMYFUNCTION("""COMPUTED_VALUE"""),"0.5") -> 0.5 | O11: =IFERROR(__xludf.DUMMYFUNCTION("""COMPUTED_VALUE"""),"5") -> 5 | P11: =IFERROR(__xludf.DUMMYFUNCTION("""COMPUTED_VALUE"""),"10") -> 10 | Q11: =IFERROR(__xludf.DUMMYFUNCTION("""COMPUTED_VALUE"""),"0.5") -> 0.5 | R11: =IFERROR(__xludf.DUMMYFUNCTION("""COMPUTED_VALUE"""),"0.571") -> 0.571 | S11: =IFERROR(__xludf.DUMMYFUNCTION("""COMPUTED_VALUE"""),"3") -> 3 | T11: =IFERROR(__xludf.DUMMYFUNCTION("""COMPUTED_VALUE"""),"4") -> 4 | U11: =IFERROR(__xludf.DUMMYFUNCTION("""COMPUTED_VALUE"""),"0.75") -> 0.75 | V11: =IFERROR(__xludf.DUMMYFUNCTION("""COMPUTED_VALUE"""),"1") -> 1 | W11: =IFERROR(__xludf.DUMMYFUNCTION("""COMPUTED_VALUE"""),"7") -> 7 | X11: =IFERROR(__xludf.DUMMYFUNCTION("""COMPUTED_VALUE"""),"8") -> 8 | Y11: =IFERROR(__xludf.DUMMYFUNCTION("""COMPUTED_VALUE"""),"6") -> 6 | Z11: =IFERROR(__xludf.DUMMYFUNCTION("""COMPUTED_VALUE"""),"1") -> 1 | AA11: =IFERROR(__xludf.DUMMYFUNCTION("""COMPUTED_VALUE"""),"1") -> 1 | AB11: =IFERROR(__xludf.DUMMYFUNCTION("""COMPUTED_VALUE"""),"2") -> 2 | AC11: =IFERROR(__xludf.DUMMYFUNCTION("""COMPUTED_VALUE"""),"1") -> 1 | AD11: =IFERROR(__xludf.DUMMYFUNCTION("""COMPUTED_VALUE"""),"19") -> 19 | AE11: =IFERROR(__xludf.DUMMYFUNCTION("""COMPUTED_VALUE"""),"0") -> 0 | AF11: =IFERROR(__xludf.DUMMYFUNCTION("""COMPUTED_VALUE"""),"")
A12: =IFERROR(__xludf.DUMMYFUNCTION("""COMPUTED_VALUE"""),"11") -> 11 | B12: =IFERROR(__xludf.DUMMYFUNCTION("""COMPUTED_VALUE"""),"Javonte Green") -> Javonte Green | C12: =IFERROR(__xludf.DUMMYFUNCTION("""COMPUTED_VALUE"""),"33") -> 33 | D12: =IFERROR(__xludf.DUMMYFUNCTION("""COMPUTED_VALUE"""),"DET") -> DET | E12: =IFERROR(__xludf.DUMMYFUNCTION("""COMPUTED_VALUE"""),"SG") -> SG | F12: =IFERROR(__xludf.DUMMYFUNCTION("""COMPUTED_VALUE"""),"1") -> 1 | G12: =IFERROR(__xludf.DUMMYFUNCTION("""COMPUTED_VALUE"""),"0") -> 0 | H12: =IFERROR(__xludf.DUMMYFUNCTION("""COMPUTED_VALUE"""),"18") -> 18 | I12: =IFERROR(__xludf.DUMMYFUNCTION("""COMPUTED_VALUE"""),"5") -> 5 | J12: =IFERROR(__xludf.DUMMYFUNCTION("""COMPUTED_VALUE"""),"10") -> 10 | K12: =IFERROR(__xludf.DUMMYFUNCTION("""COMPUTED_VALUE"""),"0.5") -> 0.5 | L12: =IFERROR(__xludf.DUMMYFUNCTION("""COMPUTED_VALUE"""),"5") -> 5 | M12: =IFERROR(__xludf.DUMMYFUNCTION("""COMPUTED_VALUE"""),"8") -> 8 | N12: =IFERROR(__xludf.DUMMYFUNCTION("""COMPUTED_VALUE"""),"0.625") -> 0.625 | O12: =IFERROR(__xludf.DUMMYFUNCTION("""COMPUTED_VALUE"""),"0") -> 0 | P12: =IFERROR(__xludf.DUMMYFUNCTION("""COMPUTED_VALUE"""),"2") -> 2 | Q12: =IFERROR(__xludf.DUMMYFUNCTION("""COMPUTED_VALUE"""),"0") -> 0 | R12: =IFERROR(__xludf.DUMMYFUNCTION("""COMPUTED_VALUE"""),"0.75") -> 0.75 | S12: =IFERROR(__xludf.DUMMYFUNCTION("""COMPUTED_VALUE"""),"4") -> 4 | T12: =IFERROR(__xludf.DUMMYFUNCTION("""COMPUTED_VALUE"""),"4") -> 4 | U12: =IFERROR(__xludf.DUMMYFUNCTION("""COMPUTED_VALUE"""),"1.000") -> 1.000 | V12: =IFERROR(__xludf.DUMMYFUNCTION("""COMPUTED_VALUE"""),"1") -> 1 | W12: =IFERROR(__xludf.DUMMYFUNCTION("""COMPUTED_VALUE"""),"3") -> 3 | X12: =IFERROR(__xludf.DUMMYFUNCTION("""COMPUTED_VALUE"""),"4") -> 4 | Y12: =IFERROR(__xludf.DUMMYFUNCTION("""COMPUTED_VALUE"""),"0") -> 0 | Z12: =IFERROR(__xludf.DUMMYFUNCTION("""COMPUTED_VALUE"""),"0") -> 0 | AA12: =IFERROR(__xludf.DUMMYFUNCTION("""COMPUTED_VALUE"""),"0") -> 0 | AB12: =IFERROR(__xludf.DUMMYFUNCTION("""COMPUTED_VALUE"""),"0") -> 0 | AC12: =IFERROR(__xludf.DUMMYFUNCTION("""COMPUTED_VALUE"""),"2") -> 2 | AD12: =IFERROR(__xludf.DUMMYFUNCTION("""COMPUTED_VALUE"""),"19") -> 19 | AE12: =IFERROR(__xludf.DUMMYFUNCTION("""COMPUTED_VALUE"""),"0") -> 0 | AF12: =IFERROR(__xludf.DUMMYFUNCTION("""COMPUTED_VALUE"""),"")
A13: =IFERROR(__xludf.DUMMYFUNCTION("""COMPUTED_VALUE"""),"12") -> 12 | B13: =IFERROR(__xludf.DUMMYFUNCTION("""COMPUTED_VALUE"""),"Karl-Anthony Towns") -> Karl-Anthony Towns | C13: =IFERROR(__xludf.DUMMYFUNCTION("""COMPUTED_VALUE"""),"31") -> 31 | D13: =IFERROR(__xludf.DUMMYFUNCTION("""COMPUTED_VALUE"""),"NYK") -> NYK | E13: =IFERROR(__xludf.DUMMYFUNCTION("""COMPUTED_VALUE"""),"C") -> C | F13: =IFERROR(__xludf.DUMMYFUNCTION("""COMPUTED_VALUE"""),"1") -> 1 | G13: =IFERROR(__xludf.DUMMYFUNCTION("""COMPUTED_VALUE"""),"1") -> 1 | H13: =IFERROR(__xludf.DUMMYFUNCTION("""COMPUTED_VALUE"""),"24") -> 24 | I13: =IFERROR(__xludf.DUMMYFUNCTION("""COMPUTED_VALUE"""),"6") -> 6 | J13: =IFERROR(__xludf.DUMMYFUNCTION("""COMPUTED_VALUE"""),"9") -> 9 | K13: =IFERROR(__xludf.DUMMYFUNCTION("""COMPUTED_VALUE"""),"0.667") -> 0.667 | L13: =IFERROR(__xludf.DUMMYFUNCTION("""COMPUTED_VALUE"""),"3") -> 3 | M13: =IFERROR(__xludf.DUMMYFUNCTION("""COMPUTED_VALUE"""),"4") -> 4 | N13: =IFERROR(__xludf.DUMMYFUNCTION("""COMPUTED_VALUE"""),"0.75") -> 0.75 | O13: =IFERROR(__xludf.DUMMYFUNCTION("""COMPUTED_VALUE"""),"3") -> 3 | P13: =IFERROR(__xludf.DUMMYFUNCTION("""COMPUTED_VALUE"""),"5") -> 5 | Q13: =IFERROR(__xludf.DUMMYFUNCTION("""COMPUTED_VALUE"""),"0.6") -> 0.6 | R13: =IFERROR(__xludf.DUMMYFUNCTION("""COMPUTED_VALUE"""),"0.833") -> 0.833 | S13: =IFERROR(__xludf.DUMMYFUNCTION("""COMPUTED_VALUE"""),"4") -> 4 | T13: =IFERROR(__xludf.DUMMYFUNCTION("""COMPUTED_VALUE"""),"7") -> 7 | U13: =IFERROR(__xludf.DUMMYFUNCTION("""COMPUTED_VALUE"""),"0.571") -> 0.571 | V13: =IFERROR(__xludf.DUMMYFUNCTION("""COMPUTED_VALUE"""),"3") -> 3 | W13: =IFERROR(__xludf.DUMMYFUNCTION("""COMPUTED_VALUE"""),"9") -> 9 | X13: =IFERROR(__xludf.DUMMYFUNCTION("""COMPUTED_VALUE"""),"12") -> 12 | Y13: =IFERROR(__xludf.DUMMYFUNCTION("""COMPUTED_VALUE"""),"1") -> 1 | Z13: =IFERROR(__xludf.DUMMYFUNCTION("""COMPUTED_VALUE"""),"1") -> 1 | AA13: =IFERROR(__xludf.DUMMYFUNCTION("""COMPUTED_VALUE"""),"2") -> 2 | AB13: =IFERROR(__xludf.DUMMYFUNCTION("""COMPUTED_VALUE"""),"4") -> 4 | AC13: =IFERROR(__xludf.DUMMYFUNCTION("""COMPUTED_VALUE"""),"4") -> 4 | AD13: =IFERROR(__xludf.DUMMYFUNCTION("""COMPUTED_VALUE"""),"19") -> 19 | AE13: =IFERROR(__xludf.DUMMYFUNCTION("""COMPUTED_VALUE"""),"0") -> 0 | AF13: =IFERROR(__xludf.DUMMYFUNCTION("""COMPUTED_VALUE"""),"")
A14: =IFERROR(__xludf.DUMMYFUNCTION("""COMPUTED_VALUE"""),"13") -> 13 | B14: =IFERROR(__xludf.DUMMYFUNCTION("""COMPUTED_VALUE"""),"Dylan Harper") -> Dylan Harper | C14: =IFERROR(__xludf.DUMMYFUNCTION("""COMPUTED_VALUE"""),"20") -> 20 | D14: =IFERROR(__xludf.DUMMYFUNCTION("""COMPUTED_VALUE"""),"SAS") -> SAS | E14: =IFERROR(__xludf.DUMMYFUNCTION("""COMPUTED_VALUE"""),"SG") -> SG | F14: =IFERROR(__xludf.DUMMYFUNCTION("""COMPUTED_VALUE"""),"1") -> 1 | G14: =IFERROR(__xludf.DUMMYFUNCTION("""COMPUTED_VALUE"""),"1") -> 1 | H14: =IFERROR(__xludf.DUMMYFUNCTION("""COMPUTED_VALUE"""),"32") -> 32 | I14: =IFERROR(__xludf.DUMMYFUNCTION("""COMPUTED_VALUE"""),"7") -> 7 | J14: =IFERROR(__xludf.DUMMYFUNCTION("""COMPUTED_VALUE"""),"17") -> 17 | K14: =IFERROR(__xludf.DUMMYFUNCTION("""COMPUTED_VALUE"""),"0.412") -> 0.412 | L14: =IFERROR(__xludf.DUMMYFUNCTION("""COMPUTED_VALUE"""),"0") -> 0 | M14: =IFERROR(__xludf.DUMMYFUNCTION("""COMPUTED_VALUE"""),"2") -> 2 | N14: =IFERROR(__xludf.DUMMYFUNCTION("""COMPUTED_VALUE"""),"0") -> 0 | O14: =IFERROR(__xludf.DUMMYFUNCTION("""COMPUTED_VALUE"""),"7") -> 7 | P14: =IFERROR(__xludf.DUMMYFUNCTION("""COMPUTED_VALUE"""),"15") -> 15 | Q14: =IFERROR(__xludf.DUMMYFUNCTION("""COMPUTED_VALUE"""),"0.467") -> 0.467 | R14: =IFERROR(__xludf.DUMMYFUNCTION("""COMPUTED_VALUE"""),"0.412") -> 0.412 | S14: =IFERROR(__xludf.DUMMYFUNCTION("""COMPUTED_VALUE"""),"4") -> 4 | T14: =IFERROR(__xludf.DUMMYFUNCTION("""COMPUTED_VALUE"""),"4") -> 4 | U14: =IFERROR(__xludf.DUMMYFUNCTION("""COMPUTED_VALUE"""),"1.000") -> 1.000 | V14: =IFERROR(__xludf.DUMMYFUNCTION("""COMPUTED_VALUE"""),"2") -> 2 | W14: =IFERROR(__xludf.DUMMYFUNCTION("""COMPUTED_VALUE"""),"5") -> 5 | X14: =IFERROR(__xludf.DUMMYFUNCTION("""COMPUTED_VALUE"""),"7") -> 7 | Y14: =IFERROR(__xludf.DUMMYFUNCTION("""COMPUTED_VALUE"""),"5") -> 5 | Z14: =IFERROR(__xludf.DUMMYFUNCTION("""COMPUTED_VALUE"""),"0") -> 0 | AA14: =IFERROR(__xludf.DUMMYFUNCTION("""COMPUTED_VALUE"""),"0") -> 0 | AB14: =IFERROR(__xludf.DUMMYFUNCTION("""COMPUTED_VALUE"""),"2") -> 2 | AC14: =IFERROR(__xludf.DUMMYFUNCTION("""COMPUTED_VALUE"""),"5") -> 5 | AD14: =IFERROR(__xludf.DUMMYFUNCTION("""COMPUTED_VALUE"""),"18") -> 18 | AE14: =IFERROR(__xludf.DUMMYFUNCTION("""COMPUTED_VALUE"""),"0") -> 0 | AF14: =IFERROR(__xludf.DUMMYFUNCTION("""COMPUTED_VALUE"""),"")
A15: =IFERROR(__xludf.DUMMYFUNCTION("""COMPUTED_VALUE"""),"14") -> 14 | B15: =IFERROR(__xludf.DUMMYFUNCTION("""COMPUTED_VALUE"""),"Payton Pritchard") -> Payton Pritchard | C15: =IFERROR(__xludf.DUMMYFUNCTION("""COMPUTED_VALUE"""),"29") -> 29 | D15: =IFERROR(__xludf.DUMMYFUNCTION("""COMPUTED_VALUE"""),"BOS") -> BOS | E15: =IFERROR(__xludf.DUMMYFUNCTION("""COMPUTED_VALUE"""),"PG") -> PG | F15: =IFERROR(__xludf.DUMMYFUNCTION("""COMPUTED_VALUE"""),"1") -> 1 | G15: =IFERROR(__xludf.DUMMYFUNCTION("""COMPUTED_VALUE"""),"0") -> 0 | H15: =IFERROR(__xludf.DUMMYFUNCTION("""COMPUTED_VALUE"""),"28") -> 28 | I15: =IFERROR(__xludf.DUMMYFUNCTION("""COMPUTED_VALUE"""),"4") -> 4 | J15: =IFERROR(__xludf.DUMMYFUNCTION("""COMPUTED_VALUE"""),"9") -> 9 | K15: =IFERROR(__xludf.DUMMYFUNCTION("""COMPUTED_VALUE"""),"0.444") -> 0.444 | L15: =IFERROR(__xludf.DUMMYFUNCTION("""COMPUTED_VALUE"""),"2") -> 2 | M15: =IFERROR(__xludf.DUMMYFUNCTION("""COMPUTED_VALUE"""),"5") -> 5 | N15: =IFERROR(__xludf.DUMMYFUNCTION("""COMPUTED_VALUE"""),"0.4") -> 0.4 | O15: =IFERROR(__xludf.DUMMYFUNCTION("""COMPUTED_VALUE"""),"2") -> 2 | P15: =IFERROR(__xludf.DUMMYFUNCTION("""COMPUTED_VALUE"""),"4") -> 4 | Q15: =IFERROR(__xludf.DUMMYFUNCTION("""COMPUTED_VALUE"""),"0.5") -> 0.5 | R15: =IFERROR(__xludf.DUMMYFUNCTION("""COMPUTED_VALUE"""),"0.556") -> 0.556 | S15: =IFERROR(__xludf.DUMMYFUNCTION("""COMPUTED_VALUE"""),"7") -> 7 | T15: =IFERROR(__xludf.DUMMYFUNCTION("""COMPUTED_VALUE"""),"8") -> 8 | U15: =IFERROR(__xludf.DUMMYFUNCTION("""COMPUTED_VALUE"""),"0.875") -> 0.875 | V15: =IFERROR(__xludf.DUMMYFUNCTION("""COMPUTED_VALUE"""),"2") -> 2 | W15: =IFERROR(__xludf.DUMMYFUNCTION("""COMPUTED_VALUE"""),"2") -> 2 | X15: =IFERROR(__xludf.DUMMYFUNCTION("""COMPUTED_VALUE"""),"4") -> 4 | Y15: =IFERROR(__xludf.DUMMYFUNCTION("""COMPUTED_VALUE"""),"1") -> 1 | Z15: =IFERROR(__xludf.DUMMYFUNCTION("""COMPUTED_VALUE"""),"0") -> 0 | AA15: =IFERROR(__xludf.DUMMYFUNCTION("""COMPUTED_VALUE"""),"0") -> 0 | AB15: =IFERROR(__xludf.DUMMYFUNCTION("""COMPUTED_VALUE"""),"0") -> 0 | AC15: =IFERROR(__xludf.DUMMYFUNCTION("""COMPUTED_VALUE"""),"2") -> 2 | AD15: =IFERROR(__xludf.DUMMYFUNCTION("""COMPUTED_VALUE"""),"17") -> 17 | AE15: =IFERROR(__xludf.DUMMYFUNCTION("""COMPUTED_VALUE"""),"0") -> 0 | AF15: =IFERROR(__xludf.DUMMYFUNCTION("""COMPUTED_VALUE"""),"")
A16: =IFERROR(__xludf.DUMMYFUNCTION("""COMPUTED_VALUE"""),"15") -> 15 | B16: =IFERROR(__xludf.DUMMYFUNCTION("""COMPUTED_VALUE"""),"Derrick White") -> Derrick White | C16: =IFERROR(__xludf.DUMMYFUNCTION("""COMPUTED_VALUE"""),"32") -> 32 | D16: =IFERROR(__xludf.DUMMYFUNCTION("""COMPUTED_VALUE"""),"BOS") -> BOS | E16: =IFERROR(__xludf.DUMMYFUNCTION("""COMPUTED_VALUE"""),"SG") -> SG | F16: =IFERROR(__xludf.DUMMYFUNCTION("""COMPUTED_VALUE"""),"1") -> 1 | G16: =IFERROR(__xludf.DUMMYFUNCTION("""COMPUTED_VALUE"""),"1") -> 1 | H16: =IFERROR(__xludf.DUMMYFUNCTION("""COMPUTED_VALUE"""),"36") -> 36 | I16: =IFERROR(__xludf.DUMMYFUNCTION("""COMPUTED_VALUE"""),"7") -> 7 | J16: =IFERROR(__xludf.DUMMYFUNCTION("""COMPUTED_VALUE"""),"13") -> 13 | K16: =IFERROR(__xludf.DUMMYFUNCTION("""COMPUTED_VALUE"""),"0.538") -> 0.538 | L16: =IFERROR(__xludf.DUMMYFUNCTION("""COMPUTED_VALUE"""),"3") -> 3 | M16: =IFERROR(__xludf.DUMMYFUNCTION("""COMPUTED_VALUE"""),"7") -> 7 | N16: =IFERROR(__xludf.DUMMYFUNCTION("""COMPUTED_VALUE"""),"0.429") -> 0.429 | O16: =IFERROR(__xludf.DUMMYFUNCTION("""COMPUTED_VALUE"""),"4") -> 4 | P16: =IFERROR(__xludf.DUMMYFUNCTION("""COMPUTED_VALUE"""),"6") -> 6 | Q16: =IFERROR(__xludf.DUMMYFUNCTION("""COMPUTED_VALUE"""),"0.667") -> 0.667 | R16: =IFERROR(__xludf.DUMMYFUNCTION("""COMPUTED_VALUE"""),"0.654") -> 0.654 | S16: =IFERROR(__xludf.DUMMYFUNCTION("""COMPUTED_VALUE"""),"0") -> 0 | T16: =IFERROR(__xludf.DUMMYFUNCTION("""COMPUTED_VALUE"""),"0") -> 0 | U16: =IFERROR(__xludf.DUMMYFUNCTION("""COMPUTED_VALUE"""),"") | V16: =IFERROR(__xludf.DUMMYFUNCTION("""COMPUTED_VALUE"""),"1") -> 1 | W16: =IFERROR(__xludf.DUMMYFUNCTION("""COMPUTED_VALUE"""),"0") -> 0 | X16: =IFERROR(__xludf.DUMMYFUNCTION("""COMPUTED_VALUE"""),"1") -> 1 | Y16: =IFERROR(__xludf.DUMMYFUNCTION("""COMPUTED_VALUE"""),"8") -> 8 | Z16: =IFERROR(__xludf.DUMMYFUNCTION("""COMPUTED_VALUE"""),"1") -> 1 | AA16: =IFERROR(__xludf.DUMMYFUNCTION("""COMPUTED_VALUE"""),"0") -> 0 | AB16: =IFERROR(__xludf.DUMMYFUNCTION("""COMPUTED_VALUE"""),"4") -> 4 | AC16: =IFERROR(__xludf.DUMMYFUNCTION("""COMPUTED_VALUE"""),"2") -> 2 | AD16: =IFERROR(__xludf.DUMMYFUNCTION("""COMPUTED_VALUE"""),"17") -> 17 | AE16: =IFERROR(__xludf.DUMMYFUNCTION("""COMPUTED_VALUE"""),"0") -> 0 | AF16: =IFERROR(__xludf.DUMMYFUNCTION("""COMPUTED_VALUE"""),"")
A17: =IFERROR(__xludf.DUMMYFUNCTION("""COMPUTED_VALUE"""),"16") -> 16 | B17: =IFERROR(__xludf.DUMMYFUNCTION("""COMPUTED_VALUE"""),"De'Aaron Fox") -> De'Aaron Fox | C17: =IFERROR(__xludf.DUMMYFUNCTION("""COMPUTED_VALUE"""),"29") -> 29 | D17: =IFERROR(__xludf.DUMMYFUNCTION("""COMPUTED_VALUE"""),"SAS") -> SAS | E17: =IFERROR(__xludf.DUMMYFUNCTION("""COMPUTED_VALUE"""),"PG") -> PG | F17: =IFERROR(__xludf.DUMMYFUNCTION("""COMPUTED_VALUE"""),"1") -> 1 | G17: =IFERROR(__xludf.DUMMYFUNCTION("""COMPUTED_VALUE"""),"1") -> 1 | H17: =IFERROR(__xludf.DUMMYFUNCTION("""COMPUTED_VALUE"""),"32") -> 32 | I17: =IFERROR(__xludf.DUMMYFUNCTION("""COMPUTED_VALUE"""),"6") -> 6 | J17: =IFERROR(__xludf.DUMMYFUNCTION("""COMPUTED_VALUE"""),"9") -> 9 | K17: =IFERROR(__xludf.DUMMYFUNCTION("""COMPUTED_VALUE"""),"0.667") -> 0.667 | L17: =IFERROR(__xludf.DUMMYFUNCTION("""COMPUTED_VALUE"""),"0") -> 0 | M17: =IFERROR(__xludf.DUMMYFUNCTION("""COMPUTED_VALUE"""),"2") -> 2 | N17: =IFERROR(__xludf.DUMMYFUNCTION("""COMPUTED_VALUE"""),"0") -> 0 | O17: =IFERROR(__xludf.DUMMYFUNCTION("""COMPUTED_VALUE"""),"6") -> 6 | P17: =IFERROR(__xludf.DUMMYFUNCTION("""COMPUTED_VALUE"""),"7") -> 7 | Q17: =IFERROR(__xludf.DUMMYFUNCTION("""COMPUTED_VALUE"""),"0.857") -> 0.857 | R17: =IFERROR(__xludf.DUMMYFUNCTION("""COMPUTED_VALUE"""),"0.667") -> 0.667 | S17: =IFERROR(__xludf.DUMMYFUNCTION("""COMPUTED_VALUE"""),"2") -> 2 | T17: =IFERROR(__xludf.DUMMYFUNCTION("""COMPUTED_VALUE"""),"3") -> 3 | U17: =IFERROR(__xludf.DUMMYFUNCTION("""COMPUTED_VALUE"""),"0.667") -> 0.667 | V17: =IFERROR(__xludf.DUMMYFUNCTION("""COMPUTED_VALUE"""),"0") -> 0 | W17: =IFERROR(__xludf.DUMMYFUNCTION("""COMPUTED_VALUE"""),"7") -> 7 | X17: =IFERROR(__xludf.DUMMYFUNCTION("""COMPUTED_VALUE"""),"7") -> 7 | Y17: =IFERROR(__xludf.DUMMYFUNCTION("""COMPUTED_VALUE"""),"7") -> 7 | Z17: =IFERROR(__xludf.DUMMYFUNCTION("""COMPUTED_VALUE"""),"1") -> 1 | AA17: =IFERROR(__xludf.DUMMYFUNCTION("""COMPUTED_VALUE"""),"0") -> 0 | AB17: =IFERROR(__xludf.DUMMYFUNCTION("""COMPUTED_VALUE"""),"2") -> 2 | AC17: =IFERROR(__xludf.DUMMYFUNCTION("""COMPUTED_VALUE"""),"1") -> 1 | AD17: =IFERROR(__xludf.DUMMYFUNCTION("""COMPUTED_VALUE"""),"14") -> 14 | AE17: =IFERROR(__xludf.DUMMYFUNCTION("""COMPUTED_VALUE"""),"0") -> 0 | AF17: =IFERROR(__xludf.DUMMYFUNCTION("""COMPUTED_VALUE"""),"")
A18: =IFERROR(__xludf.DUMMYFUNCTION("""COMPUTED_VALUE"""),"17") -> 17 | B18: =IFERROR(__xludf.DUMMYFUNCTION("""COMPUTED_VALUE"""),"Josh Hart") -> Josh Hart | C18: =IFERROR(__xludf.DUMMYFUNCTION("""COMPUTED_VALUE"""),"31") -> 31 | D18: =IFERROR(__xludf.DUMMYFUNCTION("""COMPUTED_VALUE"""),"NYK") -> NYK | E18: =IFERROR(__xludf.DUMMYFUNCTION("""COMPUTED_VALUE"""),"SG") -> SG | F18: =IFERROR(__xludf.DUMMYFUNCTION("""COMPUTED_VALUE"""),"1") -> 1 | G18: =IFERROR(__xludf.DUMMYFUNCTION("""COMPUTED_VALUE"""),"1") -> 1 | H18: =IFERROR(__xludf.DUMMYFUNCTION("""COMPUTED_VALUE"""),"30") -> 30 | I18: =IFERROR(__xludf.DUMMYFUNCTION("""COMPUTED_VALUE"""),"5") -> 5 | J18: =IFERROR(__xludf.DUMMYFUNCTION("""COMPUTED_VALUE"""),"10") -> 10 | K18: =IFERROR(__xludf.DUMMYFUNCTION("""COMPUTED_VALUE"""),"0.5") -> 0.5 | L18: =IFERROR(__xludf.DUMMYFUNCTION("""COMPUTED_VALUE"""),"2") -> 2 | M18: =IFERROR(__xludf.DUMMYFUNCTION("""COMPUTED_VALUE"""),"5") -> 5 | N18: =IFERROR(__xludf.DUMMYFUNCTION("""COMPUTED_VALUE"""),"0.4") -> 0.4 | O18: =IFERROR(__xludf.DUMMYFUNCTION("""COMPUTED_VALUE"""),"3") -> 3 | P18: =IFERROR(__xludf.DUMMYFUNCTION("""COMPUTED_VALUE"""),"5") -> 5 | Q18: =IFERROR(__xludf.DUMMYFUNCTION("""COMPUTED_VALUE"""),"0.6") -> 0.6 | R18: =IFERROR(__xludf.DUMMYFUNCTION("""COMPUTED_VALUE"""),"0.6") -> 0.6 | S18: =IFERROR(__xludf.DUMMYFUNCTION("""COMPUTED_VALUE"""),"2") -> 2 | T18: =IFERROR(__xludf.DUMMYFUNCTION("""COMPUTED_VALUE"""),"3") -> 3 | U18: =IFERROR(__xludf.DUMMYFUNCTION("""COMPUTED_VALUE"""),"0.667") -> 0.667 | V18: =IFERROR(__xludf.DUMMYFUNCTION("""COMPUTED_VALUE"""),"0") -> 0 | W18: =IFERROR(__xludf.DUMMYFUNCTION("""COMPUTED_VALUE"""),"7") -> 7 | X18: =IFERROR(__xludf.DUMMYFUNCTION("""COMPUTED_VALUE"""),"7") -> 7 | Y18: =IFERROR(__xludf.DUMMYFUNCTION("""COMPUTED_VALUE"""),"3") -> 3 | Z18: =IFERROR(__xludf.DUMMYFUNCTION("""COMPUTED_VALUE"""),"1") -> 1 | AA18: =IFERROR(__xludf.DUMMYFUNCTION("""COMPUTED_VALUE"""),"1") -> 1 | AB18: =IFERROR(__xludf.DUMMYFUNCTION("""COMPUTED_VALUE"""),"2") -> 2 | AC18: =IFERROR(__xludf.DUMMYFUNCTION("""COMPUTED_VALUE"""),"3") -> 3 | AD18: =IFERROR(__xludf.DUMMYFUNCTION("""COMPUTED_VALUE"""),"14") -> 14 | AE18: =IFERROR(__xludf.DUMMYFUNCTION("""COMPUTED_VALUE"""),"0") -> 0 | AF18: =IFERROR(__xludf.DUMMYFUNCTION("""COMPUTED_VALUE"""),"")
A19: =IFERROR(__xludf.DUMMYFUNCTION("""COMPUTED_VALUE"""),"18") -> 18 | B19: =IFERROR(__xludf.DUMMYFUNCTION("""COMPUTED_VALUE"""),"Chet Holmgren") -> Chet Holmgren | C19: =IFERROR(__xludf.DUMMYFUNCTION("""COMPUTED_VALUE"""),"24") -> 24 | D19: =IFERROR(__xludf.DUMMYFUNCTION("""COMPUTED_VALUE"""),"OKC") -> OKC | E19: =IFERROR(__xludf.DUMMYFUNCTION("""COMPUTED_VALUE"""),"C") -> C | F19: =IFERROR(__xludf.DUMMYFUNCTION("""COMPUTED_VALUE"""),"1") -> 1 | G19: =IFERROR(__xludf.DUMMYFUNCTION("""COMPUTED_VALUE"""),"1") -> 1 | H19: =IFERROR(__xludf.DUMMYFUNCTION("""COMPUTED_VALUE"""),"31") -> 31 | I19: =IFERROR(__xludf.DUMMYFUNCTION("""COMPUTED_VALUE"""),"3") -> 3 | J19: =IFERROR(__xludf.DUMMYFUNCTION("""COMPUTED_VALUE"""),"8") -> 8 | K19: =IFERROR(__xludf.DUMMYFUNCTION("""COMPUTED_VALUE"""),"0.375") -> 0.375 | L19: =IFERROR(__xludf.DUMMYFUNCTION("""COMPUTED_VALUE"""),"0") -> 0 | M19: =IFERROR(__xludf.DUMMYFUNCTION("""COMPUTED_VALUE"""),"1") -> 1 | N19: =IFERROR(__xludf.DUMMYFUNCTION("""COMPUTED_VALUE"""),"0") -> 0 | O19: =IFERROR(__xludf.DUMMYFUNCTION("""COMPUTED_VALUE"""),"3") -> 3 | P19: =IFERROR(__xludf.DUMMYFUNCTION("""COMPUTED_VALUE"""),"7") -> 7 | Q19: =IFERROR(__xludf.DUMMYFUNCTION("""COMPUTED_VALUE"""),"0.429") -> 0.429 | R19: =IFERROR(__xludf.DUMMYFUNCTION("""COMPUTED_VALUE"""),"0.375") -> 0.375 | S19: =IFERROR(__xludf.DUMMYFUNCTION("""COMPUTED_VALUE"""),"8") -> 8 | T19: =IFERROR(__xludf.DUMMYFUNCTION("""COMPUTED_VALUE"""),"8") -> 8 | U19: =IFERROR(__xludf.DUMMYFUNCTION("""COMPUTED_VALUE"""),"1.000") -> 1.000 | V19: =IFERROR(__xludf.DUMMYFUNCTION("""COMPUTED_VALUE"""),"4") -> 4 | W19: =IFERROR(__xludf.DUMMYFUNCTION("""COMPUTED_VALUE"""),"3") -> 3 | X19: =IFERROR(__xludf.DUMMYFUNCTION("""COMPUTED_VALUE"""),"7") -> 7 | Y19: =IFERROR(__xludf.DUMMYFUNCTION("""COMPUTED_VALUE"""),"2") -> 2 | Z19: =IFERROR(__xludf.DUMMYFUNCTION("""COMPUTED_VALUE"""),"0") -> 0 | AA19: =IFERROR(__xludf.DUMMYFUNCTION("""COMPUTED_VALUE"""),"4") -> 4 | AB19: =IFERROR(__xludf.DUMMYFUNCTION("""COMPUTED_VALUE"""),"1") -> 1 | AC19: =IFERROR(__xludf.DUMMYFUNCTION("""COMPUTED_VALUE"""),"0") -> 0 | AD19: =IFERROR(__xludf.DUMMYFUNCTION("""COMPUTED_VALUE"""),"14") -> 14 | AE19: =IFERROR(__xludf.DUMMYFUNCTION("""COMPUTED_VALUE"""),"0") -> 0 | AF19: =IFERROR(__xludf.DUMMYFUNCTION("""COMPUTED_VALUE"""),"")
A20: =IFERROR(__xludf.DUMMYFUNCTION("""COMPUTED_VALUE"""),"19") -> 19 | B20: =IFERROR(__xludf.DUMMYFUNCTION("""COMPUTED_VALUE"""),"LeBron James") -> LeBron James | C20: =IFERROR(__xludf.DUMMYFUNCTION("""COMPUTED_VALUE"""),"42") -> 42 | D20: =IFERROR(__xludf.DUMMYFUNCTION("""COMPUTED_VALUE"""),"PHI") -> PHI | E20: =IFERROR(__xludf.DUMMYFUNCTION("""COMPUTED_VALUE"""),"SF") -> SF | F20: =IFERROR(__xludf.DUMMYFUNCTION("""COMPUTED_VALUE"""),"1") -> 1 | G20: =IFERROR(__xludf.DUMMYFUNCTION("""COMPUTED_VALUE"""),"1") -> 1 | H20: =IFERROR(__xludf.DUMMYFUNCTION("""COMPUTED_VALUE"""),"34") -> 34 | I20: =IFERROR(__xludf.DUMMYFUNCTION("""COMPUTED_VALUE"""),"5") -> 5 | J20: =IFERROR(__xludf.DUMMYFUNCTION("""COMPUTED_VALUE"""),"13") -> 13 | K20: =IFERROR(__xludf.DUMMYFUNCTION("""COMPUTED_VALUE"""),"0.385") -> 0.385 | L20: =IFERROR(__xludf.DUMMYFUNCTION("""COMPUTED_VALUE"""),"0") -> 0 | M20: =IFERROR(__xludf.DUMMYFUNCTION("""COMPUTED_VALUE"""),"3") -> 3 | N20: =IFERROR(__xludf.DUMMYFUNCTION("""COMPUTED_VALUE"""),"0") -> 0 | O20: =IFERROR(__xludf.DUMMYFUNCTION("""COMPUTED_VALUE"""),"5") -> 5 | P20: =IFERROR(__xludf.DUMMYFUNCTION("""COMPUTED_VALUE"""),"10") -> 10 | Q20: =IFERROR(__xludf.DUMMYFUNCTION("""COMPUTED_VALUE"""),"0.5") -> 0.5 | R20: =IFERROR(__xludf.DUMMYFUNCTION("""COMPUTED_VALUE"""),"0.385") -> 0.385 | S20: =IFERROR(__xludf.DUMMYFUNCTION("""COMPUTED_VALUE"""),"4") -> 4 | T20: =IFERROR(__xludf.DUMMYFUNCTION("""COMPUTED_VALUE"""),"6") -> 6 | U20: =IFERROR(__xludf.DUMMYFUNCTION("""COMPUTED_VALUE"""),"0.667") -> 0.667 | V20: =IFERROR(__xludf.DUMMYFUNCTION("""COMPUTED_VALUE"""),"1") -> 1 | W20: =IFERROR(__xludf.DUMMYFUNCTION("""COMPUTED_VALUE"""),"8") -> 8 | X20: =IFERROR(__xludf.DUMMYFUNCTION("""COMPUTED_VALUE"""),"9") -> 9 | Y20: =IFERROR(__xludf.DUMMYFUNCTION("""COMPUTED_VALUE"""),"7") -> 7 | Z20: =IFERROR(__xludf.DUMMYFUNCTION("""COMPUTED_VALUE"""),"1") -> 1 | AA20: =IFERROR(__xludf.DUMMYFUNCTION("""COMPUTED_VALUE"""),"1") -> 1 | AB20: =IFERROR(__xludf.DUMMYFUNCTION("""COMPUTED_VALUE"""),"1") -> 1 | AC20: =IFERROR(__xludf.DUMMYFUNCTION("""COMPUTED_VALUE"""),"4") -> 4 | AD20: =IFERROR(__xludf.DUMMYFUNCTION("""COMPUTED_VALUE"""),"14") -> 14 | AE20: =IFERROR(__xludf.DUMMYFUNCTION("""COMPUTED_VALUE"""),"0") -> 0 | AF20: =IFERROR(__xludf.DUMMYFUNCTION("""COMPUTED_VALUE"""),"")
A21: =IFERROR(__xludf.DUMMYFUNCTION("""COMPUTED_VALUE"""),"20") -> 20 | B21: =IFERROR(__xludf.DUMMYFUNCTION("""COMPUTED_VALUE"""),"Joel Embiid") -> Joel Embiid | C21: =IFERROR(__xludf.DUMMYFUNCTION("""COMPUTED_VALUE"""),"32") -> 32 | D21: =IFERROR(__xludf.DUMMYFUNCTION("""COMPUTED_VALUE"""),"PHI") -> PHI | E21: =IFERROR(__xludf.DUMMYFUNCTION("""COMPUTED_VALUE"""),"C") -> C | F21: =IFERROR(__xludf.DUMMYFUNCTION("""COMPUTED_VALUE"""),"1") -> 1 | G21: =IFERROR(__xludf.DUMMYFUNCTION("""COMPUTED_VALUE"""),"1") -> 1 | H21: =IFERROR(__xludf.DUMMYFUNCTION("""COMPUTED_VALUE"""),"33") -> 33 | I21: =IFERROR(__xludf.DUMMYFUNCTION("""COMPUTED_VALUE"""),"4") -> 4 | J21: =IFERROR(__xludf.DUMMYFUNCTION("""COMPUTED_VALUE"""),"15") -> 15 | K21: =IFERROR(__xludf.DUMMYFUNCTION("""COMPUTED_VALUE"""),"0.267") -> 0.267 | L21: =IFERROR(__xludf.DUMMYFUNCTION("""COMPUTED_VALUE"""),"2") -> 2 | M21: =IFERROR(__xludf.DUMMYFUNCTION("""COMPUTED_VALUE"""),"7") -> 7 | N21: =IFERROR(__xludf.DUMMYFUNCTION("""COMPUTED_VALUE"""),"0.286") -> 0.286 | O21: =IFERROR(__xludf.DUMMYFUNCTION("""COMPUTED_VALUE"""),"2") -> 2 | P21: =IFERROR(__xludf.DUMMYFUNCTION("""COMPUTED_VALUE"""),"8") -> 8 | Q21: =IFERROR(__xludf.DUMMYFUNCTION("""COMPUTED_VALUE"""),"0.25") -> 0.25 | R21: =IFERROR(__xludf.DUMMYFUNCTION("""COMPUTED_VALUE"""),"0.333") -> 0.333 | S21: =IFERROR(__xludf.DUMMYFUNCTION("""COMPUTED_VALUE"""),"3") -> 3 | T21: =IFERROR(__xludf.DUMMYFUNCTION("""COMPUTED_VALUE"""),"4") -> 4 | U21: =IFERROR(__xludf.DUMMYFUNCTION("""COMPUTED_VALUE"""),"0.75") -> 0.75 | V21: =IFERROR(__xludf.DUMMYFUNCTION("""COMPUTED_VALUE"""),"2") -> 2 | W21: =IFERROR(__xludf.DUMMYFUNCTION("""COMPUTED_VALUE"""),"9") -> 9 | X21: =IFERROR(__xludf.DUMMYFUNCTION("""COMPUTED_VALUE"""),"11") -> 11 | Y21: =IFERROR(__xludf.DUMMYFUNCTION("""COMPUTED_VALUE"""),"6") -> 6 | Z21: =IFERROR(__xludf.DUMMYFUNCTION("""COMPUTED_VALUE"""),"2") -> 2 | AA21: =IFERROR(__xludf.DUMMYFUNCTION("""COMPUTED_VALUE"""),"3") -> 3 | AB21: =IFERROR(__xludf.DUMMYFUNCTION("""COMPUTED_VALUE"""),"4") -> 4 | AC21: =IFERROR(__xludf.DUMMYFUNCTION("""COMPUTED_VALUE"""),"3") -> 3 | AD21: =IFERROR(__xludf.DUMMYFUNCTION("""COMPUTED_VALUE"""),"13") -> 13 | AE21: =IFERROR(__xludf.DUMMYFUNCTION("""COMPUTED_VALUE"""),"0") -> 0 | AF21: =IFERROR(__xludf.DUMMYFUNCTION("""COMPUTED_VALUE"""),"")
A22: =IFERROR(__xludf.DUMMYFUNCTION("""COMPUTED_VALUE"""),"21") -> 21 | B22: =IFERROR(__xludf.DUMMYFUNCTION("""COMPUTED_VALUE"""),"Anfernee Simons") -> Anfernee Simons | C22: =IFERROR(__xludf.DUMMYFUNCTION("""COMPUTED_VALUE"""),"27") -> 27 | D22: =IFERROR(__xludf.DUMMYFUNCTION("""COMPUTED_VALUE"""),"PHI") -> PHI | E22: =IFERROR(__xludf.DUMMYFUNCTION("""COMPUTED_VALUE"""),"SG") -> SG | F22: =IFERROR(__xludf.DUMMYFUNCTION("""COMPUTED_VALUE"""),"1") -> 1 | G22: =IFERROR(__xludf.DUMMYFUNCTION("""COMPUTED_VALUE"""),"0") -> 0 | H22: =IFERROR(__xludf.DUMMYFUNCTION("""COMPUTED_VALUE"""),"25") -> 25 | I22: =IFERROR(__xludf.DUMMYFUNCTION("""COMPUTED_VALUE"""),"5") -> 5 | J22: =IFERROR(__xludf.DUMMYFUNCTION("""COMPUTED_VALUE"""),"10") -> 10 | K22: =IFERROR(__xludf.DUMMYFUNCTION("""COMPUTED_VALUE"""),"0.5") -> 0.5 | L22: =IFERROR(__xludf.DUMMYFUNCTION("""COMPUTED_VALUE"""),"3") -> 3 | M22: =IFERROR(__xludf.DUMMYFUNCTION("""COMPUTED_VALUE"""),"8") -> 8 | N22: =IFERROR(__xludf.DUMMYFUNCTION("""COMPUTED_VALUE"""),"0.375") -> 0.375 | O22: =IFERROR(__xludf.DUMMYFUNCTION("""COMPUTED_VALUE"""),"2") -> 2 | P22: =IFERROR(__xludf.DUMMYFUNCTION("""COMPUTED_VALUE"""),"2") -> 2 | Q22: =IFERROR(__xludf.DUMMYFUNCTION("""COMPUTED_VALUE"""),"1.000") -> 1.000 | R22: =IFERROR(__xludf.DUMMYFUNCTION("""COMPUTED_VALUE"""),"0.65") -> 0.65 | S22: =IFERROR(__xludf.DUMMYFUNCTION("""COMPUTED_VALUE"""),"0") -> 0 | T22: =IFERROR(__xludf.DUMMYFUNCTION("""COMPUTED_VALUE"""),"0") -> 0 | U22: =IFERROR(__xludf.DUMMYFUNCTION("""COMPUTED_VALUE"""),"") | V22: =IFERROR(__xludf.DUMMYFUNCTION("""COMPUTED_VALUE"""),"0") -> 0 | W22: =IFERROR(__xludf.DUMMYFUNCTION("""COMPUTED_VALUE"""),"2") -> 2 | X22: =IFERROR(__xludf.DUMMYFUNCTION("""COMPUTED_VALUE"""),"2") -> 2 | Y22: =IFERROR(__xludf.DUMMYFUNCTION("""COMPUTED_VALUE"""),"0") -> 0 | Z22: =IFERROR(__xludf.DUMMYFUNCTION("""COMPUTED_VALUE"""),"0") -> 0 | AA22: =IFERROR(__xludf.DUMMYFUNCTION("""COMPUTED_VALUE"""),"0") -> 0 | AB22: =IFERROR(__xludf.DUMMYFUNCTION("""COMPUTED_VALUE"""),"0") -> 0 | AC22: =IFERROR(__xludf.DUMMYFUNCTION("""COMPUTED_VALUE"""),"2") -> 2 | AD22: =IFERROR(__xludf.DUMMYFUNCTION("""COMPUTED_VALUE"""),"13") -> 13 | AE22: =IFERROR(__xludf.DUMMYFUNCTION("""COMPUTED_VALUE"""),"0") -> 0 | AF22: =IFERROR(__xludf.DUMMYFUNCTION("""COMPUTED_VALUE"""),"")
A23: =IFERROR(__xludf.DUMMYFUNCTION("""COMPUTED_VALUE"""),"22") -> 22 | B23: =IFERROR(__xludf.DUMMYFUNCTION("""COMPUTED_VALUE"""),"Jayson Tatum") -> Jayson Tatum | C23: =IFERROR(__xludf.DUMMYFUNCTION("""COMPUTED_VALUE"""),"28") -> 28 | D23: =IFERROR(__xludf.DUMMYFUNCTION("""COMPUTED_VALUE"""),"BOS") -> BOS | E23: =IFERROR(__xludf.DUMMYFUNCTION("""COMPUTED_VALUE"""),"PF") -> PF | F23: =IFERROR(__xludf.DUMMYFUNCTION("""COMPUTED_VALUE"""),"1") -> 1 | G23: =IFERROR(__xludf.DUMMYFUNCTION("""COMPUTED_VALUE"""),"1") -> 1 | H23: =IFERROR(__xludf.DUMMYFUNCTION("""COMPUTED_VALUE"""),"38") -> 38 | I23: =IFERROR(__xludf.DUMMYFUNCTION("""COMPUTED_VALUE"""),"6") -> 6 | J23: =IFERROR(__xludf.DUMMYFUNCTION("""COMPUTED_VALUE"""),"23") -> 23 | K23: =IFERROR(__xludf.DUMMYFUNCTION("""COMPUTED_VALUE"""),"0.261") -> 0.261 | L23: =IFERROR(__xludf.DUMMYFUNCTION("""COMPUTED_VALUE"""),"0") -> 0 | M23: =IFERROR(__xludf.DUMMYFUNCTION("""COMPUTED_VALUE"""),"7") -> 7 | N23: =IFERROR(__xludf.DUMMYFUNCTION("""COMPUTED_VALUE"""),"0") -> 0 | O23: =IFERROR(__xludf.DUMMYFUNCTION("""COMPUTED_VALUE"""),"6") -> 6 | P23: =IFERROR(__xludf.DUMMYFUNCTION("""COMPUTED_VALUE"""),"16") -> 16 | Q23: =IFERROR(__xludf.DUMMYFUNCTION("""COMPUTED_VALUE"""),"0.375") -> 0.375 | R23: =IFERROR(__xludf.DUMMYFUNCTION("""COMPUTED_VALUE"""),"0.261") -> 0.261 | S23: =IFERROR(__xludf.DUMMYFUNCTION("""COMPUTED_VALUE"""),"1") -> 1 | T23: =IFERROR(__xludf.DUMMYFUNCTION("""COMPUTED_VALUE"""),"1") -> 1 | U23: =IFERROR(__xludf.DUMMYFUNCTION("""COMPUTED_VALUE"""),"1") -> 1 | V23: =IFERROR(__xludf.DUMMYFUNCTION("""COMPUTED_VALUE"""),"1") -> 1 | W23: =IFERROR(__xludf.DUMMYFUNCTION("""COMPUTED_VALUE"""),"3") -> 3 | X23: =IFERROR(__xludf.DUMMYFUNCTION("""COMPUTED_VALUE"""),"4") -> 4 | Y23: =IFERROR(__xludf.DUMMYFUNCTION("""COMPUTED_VALUE"""),"11") -> 11 | Z23: =IFERROR(__xludf.DUMMYFUNCTION("""COMPUTED_VALUE"""),"0") -> 0 | AA23: =IFERROR(__xludf.DUMMYFUNCTION("""COMPUTED_VALUE"""),"0") -> 0 | AB23: =IFERROR(__xludf.DUMMYFUNCTION("""COMPUTED_VALUE"""),"2") -> 2 | AC23: =IFERROR(__xludf.DUMMYFUNCTION("""COMPUTED_VALUE"""),"3") -> 3 | AD23: =IFERROR(__xludf.DUMMYFUNCTION("""COMPUTED_VALUE"""),"13") -> 13 | AE23: =IFERROR(__xludf.DUMMYFUNCTION("""COMPUTED_VALUE"""),"0") -> 0 | AF23: =IFERROR(__xludf.DUMMYFUNCTION("""COMPUTED_VALUE"""),"")
A24: =IFERROR(__xludf.DUMMYFUNCTION("""COMPUTED_VALUE"""),"23") -> 23 | B24: =IFERROR(__xludf.DUMMYFUNCTION("""COMPUTED_VALUE"""),"Andre Drummond") -> Andre Drummond | C24: =IFERROR(__xludf.DUMMYFUNCTION("""COMPUTED_VALUE"""),"33") -> 33 | D24: =IFERROR(__xludf.DUMMYFUNCTION("""COMPUTED_VALUE"""),"NYK") -> NYK | E24: =IFERROR(__xludf.DUMMYFUNCTION("""COMPUTED_VALUE"""),"C") -> C | F24: =IFERROR(__xludf.DUMMYFUNCTION("""COMPUTED_VALUE"""),"1") -> 1 | G24: =IFERROR(__xludf.DUMMYFUNCTION("""COMPUTED_VALUE"""),"0") -> 0 | H24: =IFERROR(__xludf.DUMMYFUNCTION("""COMPUTED_VALUE"""),"24") -> 24 | I24: =IFERROR(__xludf.DUMMYFUNCTION("""COMPUTED_VALUE"""),"5") -> 5 | J24: =IFERROR(__xludf.DUMMYFUNCTION("""COMPUTED_VALUE"""),"13") -> 13 | K24: =IFERROR(__xludf.DUMMYFUNCTION("""COMPUTED_VALUE"""),"0.385") -> 0.385 | L24: =IFERROR(__xludf.DUMMYFUNCTION("""COMPUTED_VALUE"""),"0") -> 0 | M24: =IFERROR(__xludf.DUMMYFUNCTION("""COMPUTED_VALUE"""),"0") -> 0 | N24: =IFERROR(__xludf.DUMMYFUNCTION("""COMPUTED_VALUE"""),"") | O24: =IFERROR(__xludf.DUMMYFUNCTION("""COMPUTED_VALUE"""),"5") -> 5 | P24: =IFERROR(__xludf.DUMMYFUNCTION("""COMPUTED_VALUE"""),"13") -> 13 | Q24: =IFERROR(__xludf.DUMMYFUNCTION("""COMPUTED_VALUE"""),"0.385") -> 0.385 | R24: =IFERROR(__xludf.DUMMYFUNCTION("""COMPUTED_VALUE"""),"0.385") -> 0.385 | S24: =IFERROR(__xludf.DUMMYFUNCTION("""COMPUTED_VALUE"""),"2") -> 2 | T24: =IFERROR(__xludf.DUMMYFUNCTION("""COMPUTED_VALUE"""),"4") -> 4 | U24: =IFERROR(__xludf.DUMMYFUNCTION("""COMPUTED_VALUE"""),"0.5") -> 0.5 | V24: =IFERROR(__xludf.DUMMYFUNCTION("""COMPUTED_VALUE"""),"7") -> 7 | W24: =IFERROR(__xludf.DUMMYFUNCTION("""COMPUTED_VALUE"""),"7") -> 7 | X24: =IFERROR(__xludf.DUMMYFUNCTION("""COMPUTED_VALUE"""),"14") -> 14 | Y24: =IFERROR(__xludf.DUMMYFUNCTION("""COMPUTED_VALUE"""),"4") -> 4 | Z24: =IFERROR(__xludf.DUMMYFUNCTION("""COMPUTED_VALUE"""),"1") -> 1 | AA24: =IFERROR(__xludf.DUMMYFUNCTION("""COMPUTED_VALUE"""),"2") -> 2 | AB24: =IFERROR(__xludf.DUMMYFUNCTION("""COMPUTED_VALUE"""),"0") -> 0 | AC24: =IFERROR(__xludf.DUMMYFUNCTION("""COMPUTED_VALUE"""),"3") -> 3 | AD24: =IFERROR(__xludf.DUMMYFUNCTION("""COMPUTED_VALUE"""),"12") -> 12 | AE24: =IFERROR(__xludf.DUMMYFUNCTION("""COMPUTED_VALUE"""),"0") -> 0 | AF24: =IFERROR(__xludf.DUMMYFUNCTION("""COMPUTED_VALUE"""),"")
A25: =IFERROR(__xludf.DUMMYFUNCTION("""COMPUTED_VALUE"""),"24") -> 24 | B25: =IFERROR(__xludf.DUMMYFUNCTION("""COMPUTED_VALUE"""),"Victor Wembanyama") -> Victor Wembanyama | C25: =IFERROR(__xludf.DUMMYFUNCTION("""COMPUTED_VALUE"""),"23") -> 23 | D25: =IFERROR(__xludf.DUMMYFUNCTION("""COMPUTED_VALUE"""),"SAS") -> SAS | E25: =IFERROR(__xludf.DUMMYFUNCTION("""COMPUTED_VALUE"""),"C") -> C | F25: =IFERROR(__xludf.DUMMYFUNCTION("""COMPUTED_VALUE"""),"1") -> 1 | G25: =IFERROR(__xludf.DUMMYFUNCTION("""COMPUTED_VALUE"""),"1") -> 1 | H25: =IFERROR(__xludf.DUMMYFUNCTION("""COMPUTED_VALUE"""),"34") -> 34 | I25: =IFERROR(__xludf.DUMMYFUNCTION("""COMPUTED_VALUE"""),"1") -> 1 | J25: =IFERROR(__xludf.DUMMYFUNCTION("""COMPUTED_VALUE"""),"13") -> 13 | K25: =IFERROR(__xludf.DUMMYFUNCTION("""COMPUTED_VALUE"""),"0.077") -> 0.077 | L25: =IFERROR(__xludf.DUMMYFUNCTION("""COMPUTED_VALUE"""),"0") -> 0 | M25: =IFERROR(__xludf.DUMMYFUNCTION("""COMPUTED_VALUE"""),"4") -> 4 | N25: =IFERROR(__xludf.DUMMYFUNCTION("""COMPUTED_VALUE"""),"0") -> 0 | O25: =IFERROR(__xludf.DUMMYFUNCTION("""COMPUTED_VALUE"""),"1") -> 1 | P25: =IFERROR(__xludf.DUMMYFUNCTION("""COMPUTED_VALUE"""),"9") -> 9 | Q25: =IFERROR(__xludf.DUMMYFUNCTION("""COMPUTED_VALUE"""),"0.111") -> 0.111 | R25: =IFERROR(__xludf.DUMMYFUNCTION("""COMPUTED_VALUE"""),"0.077") -> 0.077 | S25: =IFERROR(__xludf.DUMMYFUNCTION("""COMPUTED_VALUE"""),"10") -> 10 | T25: =IFERROR(__xludf.DUMMYFUNCTION("""COMPUTED_VALUE"""),"12") -> 12 | U25: =IFERROR(__xludf.DUMMYFUNCTION("""COMPUTED_VALUE"""),"0.833") -> 0.833 | V25: =IFERROR(__xludf.DUMMYFUNCTION("""COMPUTED_VALUE"""),"2") -> 2 | W25: =IFERROR(__xludf.DUMMYFUNCTION("""COMPUTED_VALUE"""),"11") -> 11 | X25: =IFERROR(__xludf.DUMMYFUNCTION("""COMPUTED_VALUE"""),"13") -> 13 | Y25: =IFERROR(__xludf.DUMMYFUNCTION("""COMPUTED_VALUE"""),"3") -> 3 | Z25: =IFERROR(__xludf.DUMMYFUNCTION("""COMPUTED_VALUE"""),"1") -> 1 | AA25: =IFERROR(__xludf.DUMMYFUNCTION("""COMPUTED_VALUE"""),"6") -> 6 | AB25: =IFERROR(__xludf.DUMMYFUNCTION("""COMPUTED_VALUE"""),"4") -> 4 | AC25: =IFERROR(__xludf.DUMMYFUNCTION("""COMPUTED_VALUE"""),"3") -> 3 | AD25: =IFERROR(__xludf.DUMMYFUNCTION("""COMPUTED_VALUE"""),"12") -> 12 | AE25: =IFERROR(__xludf.DUMMYFUNCTION("""COMPUTED_VALUE"""),"0") -> 0 | AF25: =IFERROR(__xludf.DUMMYFUNCTION("""COMPUTED_VALUE"""),"")
